{
 "cells": [
  {
   "cell_type": "code",
   "execution_count": 2,
   "id": "74a717c3",
   "metadata": {},
   "outputs": [],
   "source": [
    "import tensorflow as tf    \n",
    "from tensorflow import keras\n",
    "from tensorflow.keras import layers\n",
    "from tensorflow.keras.datasets import mnist\n",
    "import tensorflow_hub as hub"
   ]
  },
  {
   "cell_type": "code",
   "execution_count": 3,
   "id": "a764690c",
   "metadata": {},
   "outputs": [],
   "source": [
    "#pretrained model\n",
    "(x_train, y_train), (x_test, y_test) = mnist.load_data()\n",
    "x_train = x_train.reshape(-1,28,28,1).astype(\"float32\") / 255.0\n",
    "x_test = x_test.reshape(-1,28,28,1).astype(\"float32\") / 255.0"
   ]
  },
  {
   "cell_type": "code",
   "execution_count": 5,
   "id": "3f6e0f95",
   "metadata": {},
   "outputs": [
    {
     "ename": "OSError",
     "evalue": "SavedModel file does not exist at: save_model\\{saved_model.pbtxt|saved_model.pb}",
     "output_type": "error",
     "traceback": [
      "\u001b[1;31m---------------------------------------------------------------------------\u001b[0m",
      "\u001b[1;31mOSError\u001b[0m                                   Traceback (most recent call last)",
      "Cell \u001b[1;32mIn[5], line 1\u001b[0m\n\u001b[1;32m----> 1\u001b[0m model \u001b[38;5;241m=\u001b[39m \u001b[43mkeras\u001b[49m\u001b[38;5;241;43m.\u001b[39;49m\u001b[43mmodels\u001b[49m\u001b[38;5;241;43m.\u001b[39;49m\u001b[43mload_model\u001b[49m\u001b[43m(\u001b[49m\u001b[38;5;124;43m\"\u001b[39;49m\u001b[38;5;124;43msave_model\u001b[39;49m\u001b[38;5;124;43m\"\u001b[39;49m\u001b[43m)\u001b[49m\n\u001b[0;32m      2\u001b[0m \u001b[38;5;28mprint\u001b[39m(model\u001b[38;5;241m.\u001b[39msummary())\n",
      "File \u001b[1;32mC:\\Anaconda\\lib\\site-packages\\keras\\utils\\traceback_utils.py:70\u001b[0m, in \u001b[0;36mfilter_traceback.<locals>.error_handler\u001b[1;34m(*args, **kwargs)\u001b[0m\n\u001b[0;32m     67\u001b[0m     filtered_tb \u001b[38;5;241m=\u001b[39m _process_traceback_frames(e\u001b[38;5;241m.\u001b[39m__traceback__)\n\u001b[0;32m     68\u001b[0m     \u001b[38;5;66;03m# To get the full stack trace, call:\u001b[39;00m\n\u001b[0;32m     69\u001b[0m     \u001b[38;5;66;03m# `tf.debugging.disable_traceback_filtering()`\u001b[39;00m\n\u001b[1;32m---> 70\u001b[0m     \u001b[38;5;28;01mraise\u001b[39;00m e\u001b[38;5;241m.\u001b[39mwith_traceback(filtered_tb) \u001b[38;5;28;01mfrom\u001b[39;00m \u001b[38;5;28;01mNone\u001b[39;00m\n\u001b[0;32m     71\u001b[0m \u001b[38;5;28;01mfinally\u001b[39;00m:\n\u001b[0;32m     72\u001b[0m     \u001b[38;5;28;01mdel\u001b[39;00m filtered_tb\n",
      "File \u001b[1;32mC:\\Anaconda\\lib\\site-packages\\tensorflow\\python\\saved_model\\loader_impl.py:115\u001b[0m, in \u001b[0;36mparse_saved_model\u001b[1;34m(export_dir)\u001b[0m\n\u001b[0;32m    113\u001b[0m     \u001b[38;5;28;01mraise\u001b[39;00m \u001b[38;5;167;01mIOError\u001b[39;00m(\u001b[38;5;124mf\u001b[39m\u001b[38;5;124m\"\u001b[39m\u001b[38;5;124mCannot parse file \u001b[39m\u001b[38;5;132;01m{\u001b[39;00mpath_to_pbtxt\u001b[38;5;132;01m}\u001b[39;00m\u001b[38;5;124m: \u001b[39m\u001b[38;5;132;01m{\u001b[39;00m\u001b[38;5;28mstr\u001b[39m(e)\u001b[38;5;132;01m}\u001b[39;00m\u001b[38;5;124m.\u001b[39m\u001b[38;5;124m\"\u001b[39m)\n\u001b[0;32m    114\u001b[0m \u001b[38;5;28;01melse\u001b[39;00m:\n\u001b[1;32m--> 115\u001b[0m   \u001b[38;5;28;01mraise\u001b[39;00m \u001b[38;5;167;01mIOError\u001b[39;00m(\n\u001b[0;32m    116\u001b[0m       \u001b[38;5;124mf\u001b[39m\u001b[38;5;124m\"\u001b[39m\u001b[38;5;124mSavedModel file does not exist at: \u001b[39m\u001b[38;5;132;01m{\u001b[39;00mexport_dir\u001b[38;5;132;01m}\u001b[39;00m\u001b[38;5;132;01m{\u001b[39;00mos\u001b[38;5;241m.\u001b[39mpath\u001b[38;5;241m.\u001b[39msep\u001b[38;5;132;01m}\u001b[39;00m\u001b[38;5;124m\"\u001b[39m\n\u001b[0;32m    117\u001b[0m       \u001b[38;5;124mf\u001b[39m\u001b[38;5;124m\"\u001b[39m\u001b[38;5;130;01m{{\u001b[39;00m\u001b[38;5;132;01m{\u001b[39;00mconstants\u001b[38;5;241m.\u001b[39mSAVED_MODEL_FILENAME_PBTXT\u001b[38;5;132;01m}\u001b[39;00m\u001b[38;5;124m|\u001b[39m\u001b[38;5;124m\"\u001b[39m\n\u001b[0;32m    118\u001b[0m       \u001b[38;5;124mf\u001b[39m\u001b[38;5;124m\"\u001b[39m\u001b[38;5;132;01m{\u001b[39;00mconstants\u001b[38;5;241m.\u001b[39mSAVED_MODEL_FILENAME_PB\u001b[38;5;132;01m}\u001b[39;00m\u001b[38;5;130;01m}}\u001b[39;00m\u001b[38;5;124m\"\u001b[39m)\n",
      "\u001b[1;31mOSError\u001b[0m: SavedModel file does not exist at: save_model\\{saved_model.pbtxt|saved_model.pb}"
     ]
    }
   ],
   "source": [
    "model = keras.models.load_model(\"save_model/\")\n",
    "print(model.summary())"
   ]
  },
  {
   "cell_type": "code",
   "execution_count": null,
   "id": "cdc2b7ce",
   "metadata": {},
   "outputs": [],
   "source": []
  }
 ],
 "metadata": {
  "kernelspec": {
   "display_name": "Python 3 (ipykernel)",
   "language": "python",
   "name": "python3"
  },
  "language_info": {
   "codemirror_mode": {
    "name": "ipython",
    "version": 3
   },
   "file_extension": ".py",
   "mimetype": "text/x-python",
   "name": "python",
   "nbconvert_exporter": "python",
   "pygments_lexer": "ipython3",
   "version": "3.9.17"
  }
 },
 "nbformat": 4,
 "nbformat_minor": 5
}
